<?xml version="1.0" ?>
<!-- =================================================================================== -->
<!-- |    This document was autogenerated by xacro from src/lepantilt_ros2/lepantilt_description/urdf/pantilt.urdf.xacro | -->
<!-- |    EDITING THIS FILE BY HAND IS NOT RECOMMENDED                                 | -->
<!-- =================================================================================== -->
<robot name="lepantilt">
  <!-- N⋅m (30 kgf⋅cm for STS3215) -->
  <!-- ROS 2 CONTROL -->
  <ros2_control name="lepantilt_control" type="system">
    <hardware>
      <plugin>sts_hardware_interface/STSHardwareInterface</plugin>
      <param name="serial_port">/dev/ttySERVO</param>
      <param name="baud_rate">1000000</param>
      <param name="communication_timeout_ms">100</param>
      <param name="use_sync_write">true</param>
      <param name="enable_mock_mode">false</param>
      <param name="max_velocity_steps">3400</param>
      <param name="reset_states_on_activate">true</param>
    </hardware>
    <!-- Pan axis: rotates the payload around Z (Motor ID ${pan_motor_id}) -->
    <joint name="pan_joint">
      <param name="motor_id">1</param>
      <param name="operating_mode">0</param>
      <param name="min_position">-1.5707963267948966</param>
      <param name="max_position">1.5707963267948966</param>
      <param name="max_velocity">2.60776733940559</param>
      <param name="position_center_steps">2048</param>
      <command_interface name="position"/>
      <state_interface name="position"/>
      <state_interface name="velocity"/>
      <state_interface name="effort"/>
      <state_interface name="voltage"/>
      <state_interface name="temperature"/>
      <state_interface name="current"/>
      <state_interface name="is_moving"/>
    </joint>
    <!-- Tilt axis: rotates the payload around Y (Motor ID ${tilt_motor_id}) -->
    <joint name="tilt_joint">
      <param name="motor_id">2</param>
      <param name="operating_mode">0</param>
      <param name="min_position">-1.5707963267948966</param>
      <param name="max_position">1.5707963267948966</param>
      <param name="max_velocity">2.60776733940559</param>
      <param name="position_center_steps">2646</param>
      <command_interface name="position"/>
      <state_interface name="position"/>
      <state_interface name="velocity"/>
      <state_interface name="effort"/>
      <state_interface name="voltage"/>
      <state_interface name="temperature"/>
      <state_interface name="current"/>
      <state_interface name="is_moving"/>
    </joint>
  </ros2_control>
  <!-- Standalone pantilt module instantiation -->
  <link name="base_footprint"/>
  <!-- Material definitions (referenced by links below) -->
  <material name="light_grey">
    <color rgba="0.8 0.8 0.8 1.0"/>
  </material>
  <material name="charcoal">
    <color rgba="0.15 0.15 0.15 1.0"/>
  </material>
  <!-- Mount pantilt_base_link to parent platform at specified origin -->
  <joint name="pantilt_mount_joint" type="fixed">
    <parent link="base_footprint"/>
    <child link="pantilt_base_link"/>
    <origin rpy="0 0 0" xyz="0 0 0"/>
  </joint>
  <!-- Pan-tilt base link (was "base_link" in standalone URDF) -->
  <link name="pantilt_base_link">
    <inertial>
      <mass value="1.0"/>
      <origin rpy="0 0 0" xyz="0 0 0"/>
      <inertia ixx="0.01" ixy="0" ixz="0" iyy="0.01" iyz="0" izz="0.01"/>
    </inertial>
    <visual>
      <origin rpy="0 0 1.5707963267948966" xyz="0 0 0"/>
      <geometry>
        <mesh filename="../meshes/pantilt_base.stl"/>
      </geometry>
      <material name="light_grey"/>
    </visual>
    <visual>
      <origin rpy="0 0 1.5707963267948966" xyz="0 0 0"/>
      <geometry>
        <mesh filename="../meshes/pan_motor.stl"/>
      </geometry>
      <material name="charcoal"/>
    </visual>
    <collision>
      <origin rpy="0 0 1.5707963267948966" xyz="0 0 0"/>
      <geometry>
        <mesh filename="../meshes/pantilt_base.stl"/>
      </geometry>
    </collision>
  </link>
  <!-- Pan link -->
  <link name="pan_link">
    <inertial>
      <mass value="0.119226"/>
      <origin rpy="0 0 0" xyz="-9.07886e-05 0.0590972 0.031089"/>
      <inertia ixx="5.94278e-05" ixy="0" ixz="0" iyy="5.89975e-05" iyz="0" izz="3.13712e-05"/>
    </inertial>
    <visual>
      <origin rpy="1.5707963267948966 0 1.5707963267948966" xyz="0 0 0"/>
      <geometry>
        <mesh filename="../meshes/pan_joint.stl"/>
      </geometry>
      <material name="light_grey"/>
    </visual>
    <visual>
      <origin rpy="1.5707963267948966 0 1.5707963267948966" xyz="0 0 0"/>
      <geometry>
        <mesh filename="../meshes/tilt_motor.stl"/>
      </geometry>
      <material name="charcoal"/>
    </visual>
    <collision>
      <origin rpy="1.5707963267948966 0 1.5707963267948966" xyz="0 0 0"/>
      <geometry>
        <mesh filename="../meshes/pan_joint.stl"/>
      </geometry>
    </collision>
  </link>
  <!-- Tilt link -->
  <link name="tilt_link">
    <inertial>
      <mass value="0.1"/>
      <origin rpy="0 0 0" xyz="0 0 0"/>
      <inertia ixx="0.001" ixy="0" ixz="0" iyy="0.001" iyz="0" izz="0.001"/>
    </inertial>
    <visual>
      <origin rpy="1.5707963267948966 -1.5707963267948966 0" xyz="0.119 0.07579999999999999 -0.0002"/>
      <geometry>
        <mesh filename="../meshes/tilt_joint.stl"/>
      </geometry>
      <material name="light_grey"/>
    </visual>
    <collision>
      <origin rpy="1.5707963267948966 -1.5707963267948966 0" xyz="0.119 0.07579999999999999 -0.0002"/>
      <geometry>
        <mesh filename="../meshes/tilt_joint.stl"/>
      </geometry>
    </collision>
  </link>
  <!-- For the Pan and Tilt joints below, velocity="1e6": 
    URDF requires a velocity attribute on revolute joints, but hardware-enforced
    velocity profiling makes software rate-limiting redundant and causes spurious
    "command out of limits" errors from ros2_control when joy_teleop sends large absolute
    position steps. 1e6 rad/s is physically unreachable and effectively disables the
    JointSaturationLimiter's per-cycle velocity clipping for these joints. -->
  <!-- Pan joint (revolute) -->
  <joint name="pan_joint" type="revolute">
    <parent link="pantilt_base_link"/>
    <child link="pan_link"/>
    <origin rpy="0 0 0" xyz="0.0452 0 0.0165"/>
    <axis xyz="0 0 1"/>
    <limit effort="2.942" lower="-1.5707963267948966" upper="1.5707963267948966" velocity="1e6"/>
  </joint>
  <!-- Tilt joint (revolute) -->
  <joint name="tilt_joint" type="revolute">
    <parent link="pan_link"/>
    <child link="tilt_link"/>
    <origin rpy="-1.5707963267948966 1.5707963267948966 0" xyz="0.0306 0 0.1025"/>
    <axis xyz="0 0 -1"/>
    <limit effort="2.942" lower="-1.5707963267948966" upper="1.5707963267948966" velocity="1e6"/>
  </joint>
  <!--
	  Custom OAK-D-S2 camera macro for lepantilt only.
	  This version allows direct color parameterization (r/g/b/a) for the mesh material.
	-->
  <!-- base_link of the sensor-->
  <link name="oak_link"/>
  <joint name="oak_link_center_joint" type="fixed">
    <parent link="tilt_link"/>
    <child link="oak_link"/>
    <origin rpy="-1.5707963267948966 0 -1.5707963267948966" xyz="-0.03435 -0.01 0"/>
  </joint>
  <!-- IMU frame -->
  <link name="oak_imu_frame"/>
  <joint name="oak_imu_frame_joint" type="fixed">
    <parent link="oak_link"/>
    <child link="oak_imu_frame"/>
    <origin rpy="3.141592653589793 1.5707963267948966 0" xyz="-0.008 -0.037945 -0.00079"/>
  </joint>
  <!-- Device mesh with custom color -->
  <link name="oak_link_model_origin">
    <visual>
      <origin rpy="0 0 0" xyz="0 0 0"/>
      <geometry>
        <mesh filename="../meshes/oakd_s2.stl"/>
      </geometry>
      <material name="mat">
        <color rgba="0.15 0.15 0.15 1.0"/>
      </material>
    </visual>
  </link>
  <joint name="oak_link_model_origin_joint" type="fixed">
    <parent link="oak_link"/>
    <child link="oak_link_model_origin"/>
    <origin rpy="1.5707963267948966 0 1.5707963267948966" xyz="0 0 0"/>
  </joint>
</robot>
