<?xml version="1.0" ?>
<robot name="lepantilt">
  <!-- Position mode -->
  <!-- Max hardware velocity in steps/s -->
  <!-- N⋅m (30 kgf⋅cm for STS3215) -->
  <material name="light_grey">
    <color rgba="0.8 0.8 0.8 1.0"/>
  </material>
  <material name="charcoal">
    <color rgba="0.15 0.15 0.15 1.0"/>
  </material>
  <!-- LINKS -->
  <!-- Base footprint link (empty root — KDL does not support inertia on root link) -->
  <link name="base_footprint"/>
  <!-- Base link -->
  <link name="base_link">
    <inertial>
      <mass value="1.0"/>
      <origin rpy="0 0 0" xyz="0 0 0"/>
      <inertia ixx="0.01" ixy="0" ixz="0" iyy="0.01" iyz="0" izz="0.01"/>
    </inertial>
    <visual>
      <origin rpy="0 0 1.5707963267948966" xyz="0 0 0"/>
      <geometry>
        <mesh filename="../meshes/pantilt_base.stl"/>
      </geometry>
      <material name="light_grey"/>
    </visual>
    <visual>
      <origin rpy="0 0 1.5707963267948966" xyz="0 0 0"/>
      <geometry>
        <mesh filename="../meshes/pan_motor.stl"/>
      </geometry>
      <material name="charcoal"/>
    </visual>
    <collision>
      <origin rpy="0 0 1.5707963267948966" xyz="0 0 0"/>
      <geometry>
        <mesh filename="../meshes/pantilt_base.stl"/>
      </geometry>
    </collision>
  </link>
  <!-- Pan link -->
  <link name="pan_link">
    <inertial>
      <mass value="0.119226"/>
      <origin rpy="0 0 0" xyz="-9.07886e-05 0.0590972 0.031089"/>
      <inertia ixx="5.94278e-05" ixy="0" ixz="0" iyy="5.89975e-05" iyz="0" izz="3.13712e-05"/>
    </inertial>
    <visual>
      <origin rpy="1.5707963267948966 0 1.5707963267948966" xyz="0 0 0"/>
      <geometry>
        <mesh filename="../meshes/pan_joint.stl"/>
      </geometry>
      <material name="light_grey"/>
    </visual>
    <visual>
      <origin rpy="1.5707963267948966 0 1.5707963267948966" xyz="0 0 0"/>
      <geometry>
        <mesh filename="../meshes/tilt_motor.stl"/>
      </geometry>
      <material name="charcoal"/>
    </visual>
    <collision>
      <origin rpy="1.5707963267948966 0 1.5707963267948966" xyz="0 0 0"/>
      <geometry>
        <mesh filename="../meshes/pan_joint.stl"/>
      </geometry>
    </collision>
  </link>
  <!-- Tilt link -->
  <link name="tilt_link">
    <inertial>
      <mass value="0.1"/>
      <origin rpy="0 0 0" xyz="0 0 0"/>
      <inertia ixx="0.001" ixy="0" ixz="0" iyy="0.001" iyz="0" izz="0.001"/>
    </inertial>
    <visual>
      <origin rpy="1.5707963268 -1.5707963268 0" xyz="0.119 0.0758 -0.0002"/>
      <geometry>
        <mesh filename="../meshes/tilt_joint.stl"/>
      </geometry>
      <material name="light_grey"/>
    </visual>
    <collision>
      <origin rpy="1.5707963268 -1.5707963268 0" xyz="0.119 0.0758 -0.0002"/>
      <geometry>
        <mesh filename="../meshes/tilt_joint.stl"/>
      </geometry>
    </collision>
  </link>
  <!-- JOINTS -->
  <!-- base_footprint fixed joint -->
  <joint name="base_footprint_joint" type="fixed">
    <parent link="base_footprint"/>
    <child link="base_link"/>
    <origin rpy="0 0 0" xyz="0 0 0"/>
  </joint>
  <!-- Pan joint (revolute) -->
  <joint name="pan_joint" type="revolute">
    <parent link="base_link"/>
    <child link="pan_link"/>
    <origin rpy="0 0 0" xyz="0.0452 0 0.0165"/>
    <axis xyz="0 0 1"/>
    <limit effort="2.942" lower="-2" upper="2" velocity="5.21553467881118"/>
  </joint>
  <!-- Tilt joint (revolute) -->
  <joint name="tilt_joint" type="revolute">
    <parent link="pan_link"/>
    <child link="tilt_link"/>
    <origin rpy="-1.5707963268 1.5707963268 0" xyz="0.0306 0 0.1025"/>
    <axis xyz="0 0 1"/>
    <limit effort="2.942" lower="-1.5707963268" upper="1.5707963268" velocity="5.21553467881118"/>
  </joint>
  <!-- OAK-D-S2 camera (fixed to tilt_link) -->
  <link name="oak"/>

  <joint name="oak_mount_joint" type="fixed">
    <parent link="tilt_link"/>
    <child link="oak"/>
    <origin xyz="-0.03435 -0.01 0.0" rpy="-1.5707963267948966 0.0 -1.5707963267948966"/>
  </joint>

  <link name="oak_model_origin">
    <visual>
      <origin xyz="0 0 0" rpy="0 0 0"/>
      <geometry>
        <mesh filename="../meshes/oakd_s2.stl"/>
      </geometry>
      <material name="charcoal"/>
    </visual>
  </link>

  <joint name="oak_model_origin_joint" type="fixed">
    <parent link="oak"/>
    <child link="oak_model_origin"/>
    <origin xyz="0 0 0" rpy="1.5707963267948966 0 1.5707963267948966"/>
  </joint>

  <link name="oak_rgb_camera_frame"/>

  <joint name="oak_rgb_camera_joint" type="fixed">
    <parent link="oak"/>
    <child link="oak_rgb_camera_frame"/>
    <origin xyz="0 0 0" rpy="0 0 0"/>
  </joint>

  <link name="oak_rgb_camera_optical_frame"/>

  <joint name="oak_rgb_camera_optical_joint" type="fixed">
    <parent link="oak_rgb_camera_frame"/>
    <child link="oak_rgb_camera_optical_frame"/>
    <origin xyz="0 0 0" rpy="-1.5707963267948966 0.0 -1.5707963267948966"/>
  </joint>

  <link name="oak_left_camera_frame"/>

  <joint name="oak_left_camera_joint" type="fixed">
    <parent link="oak"/>
    <child link="oak_left_camera_frame"/>
    <origin xyz="0 0.0375 0" rpy="0 0 0"/>
  </joint>

  <link name="oak_left_camera_optical_frame"/>

  <joint name="oak_left_camera_optical_joint" type="fixed">
    <parent link="oak_left_camera_frame"/>
    <child link="oak_left_camera_optical_frame"/>
    <origin xyz="0 0 0" rpy="-1.5707963267948966 0.0 -1.5707963267948966"/>
  </joint>

  <link name="oak_right_camera_frame"/>

  <joint name="oak_right_camera_joint" type="fixed">
    <parent link="oak"/>
    <child link="oak_right_camera_frame"/>
    <origin xyz="0 -0.0375 0" rpy="0 0 0"/>
  </joint>

  <link name="oak_right_camera_optical_frame"/>

  <joint name="oak_right_camera_optical_joint" type="fixed">
    <parent link="oak_right_camera_frame"/>
    <child link="oak_right_camera_optical_frame"/>
    <origin xyz="0 0 0" rpy="-1.5707963267948966 0.0 -1.5707963267948966"/>
  </joint>

  <link name="oak_imu_frame"/>

  <joint name="oak_imu_joint" type="fixed">
    <parent link="oak"/>
    <child link="oak_imu_frame"/>
    <origin xyz="-0.008 -0.037945 -0.00079" rpy="3.1415926535897932 1.5707963267948966 0.0"/>
  </joint>

  <!-- ROS 2 CONTROL -->
  <ros2_control name="lepantilt_control" type="system">
    <hardware>
      <plugin>sts_hardware_interface/STSHardwareInterface</plugin>
      <param name="serial_port">/dev/ttySERVO</param>
      <param name="baud_rate">1000000</param>
      <param name="use_sync_write">True</param>
      <param name="enable_mock_mode">False</param>
    </hardware>
    <!-- Pan axis: rotates the payload around Z (Motor ID ${pan_motor_id}) -->
    <joint name="pan_joint">
      <param name="motor_id">1</param>
      <param name="operating_mode">0</param>
      <command_interface name="position"/>
      <state_interface name="position"/>
      <state_interface name="velocity"/>
      <state_interface name="effort"/>
      <state_interface name="voltage"/>
      <state_interface name="temperature"/>
      <state_interface name="current"/>
      <state_interface name="is_moving"/>
    </joint>
    <!-- Tilt axis: rotates the payload around Y (Motor ID ${tilt_motor_id}) -->
    <joint name="tilt_joint">
      <param name="motor_id">2</param>
      <param name="operating_mode">0</param>
      <command_interface name="position"/>
      <state_interface name="position"/>
      <state_interface name="velocity"/>
      <state_interface name="effort"/>
      <state_interface name="voltage"/>
      <state_interface name="temperature"/>
      <state_interface name="current"/>
      <state_interface name="is_moving"/>
    </joint>
  </ros2_control>
</robot>
